<mujoco model="panda_with_leap_hand">
    <!-- 1) COMBINED COMPILER & OPTIONS -->
    <compiler angle="radian" meshdir="assets" autolimits="true"/>
    <option integrator="implicitfast" impratio="10" />

    <!-- 2) COMBINED DEFAULTS -->
    <default>
      <!-- Panda defaults -->
      <default class="panda">
        <material specular="0.5" shininess="0.25"/>
        <joint armature="0.1" damping="1" axis="0 0 1" range="-2.8973 2.8973" type="hinge"/>
        <general dyntype="none" biastype="affine" ctrlrange="-2.8973 2.8973" forcerange="-87 87"/>
        <default class="finger">
          <joint axis="0 1 0" type="slide" range="0 0.04"/>
        </default>
        <default class="panda/visual">
          <geom type="mesh" contype="0" conaffinity="0" group="2"/>
        </default>
        <default class="panda/collision">
          <geom type="mesh" group="3"/>
        </default>
        <site size="0.001" rgba="0.5 0.5 0.5 0.3" group="4"/>
      </default>

  <default class="2f85">
      <mesh scale="0.001 0.001 0.001"/>
      <general biastype="affine"/>

      <joint axis="0 0 1"/>
      <default class="driver">
        <joint range="0 0.9" armature="0.005" damping="0.1" solimplimit="0.95 0.99 0.001" solreflimit="0.005 1"/>
      </default>
      <default class="follower">
        <joint range="-0.872664 0.9" armature="0.001"  solimplimit="0.95 0.99 0.001" solreflimit="0.005 1"/>
      </default>
      <default class="spring_link">
        <joint range="-0.29670597283 0.9" armature="0.001" stiffness="0.05" springref="2.62" damping="0.00125"/>
      </default>
      <default class="coupler">
        <joint range="-1.57 0" armature="0.001" solimplimit="0.95 0.99 0.001" solreflimit="0.005 1"/>
      </default>

      <default class="visual">
        <geom type="mesh" contype="0" conaffinity="0" group="2" material="black"/>
      </default>
      <default class="collision">
        <geom type="mesh" group="3"/>
        <default class="pad_box1">
          <geom mass="1e-6" type="box" pos="0.043258  0 0.12"  size="0.002 0.011 0.009375" friction="0.7"
            solimp="0.95 0.99 0.001" solref="0.004 1" priority="1" rgba="0.55 0.55 0.55 1"/>
        </default>
        <default class="pad_box2">
          <geom mass="1e-6" type="box" pos="0.043258 0 0.13875" size="0.002 0.011 0.009375" friction="0.6"
            solimp="0.95 0.99 0.001" solref="0.004 1" priority="1" rgba="0.45 0.45 0.45 1"/>
        </default>
      </default>
    </default>
  </default>

    <!-- 3) COMBINED ASSETS -->
    <asset>
      <!-- Panda assets -->
      <material class="panda" name="white" rgba="1 1 1 1"/>
      <material class="panda" name="off_white" rgba="0.901961 0.921569 0.929412 1"/>
      <material class="panda" name="dark_grey" rgba="0.25 0.25 0.25 1"/>
      <material class="panda" name="green" rgba="0 1 0 1"/>
      <material class="panda" name="light_blue" rgba="0.039216 0.541176 0.780392 1"/>

      <mesh name="link0_c" file="link0.stl"/>
      <mesh name="link1_c" file="link1.stl"/>
      <mesh name="link2_c" file="link2.stl"/>
      <mesh name="link3_c" file="link3.stl"/>
      <mesh name="link4_c" file="link4.stl"/>
      <mesh name="link5_c0" file="link5_collision_0.obj"/>
      <mesh name="link5_c1" file="link5_collision_1.obj"/>
      <mesh name="link5_c2" file="link5_collision_2.obj"/>
      <mesh name="link6_c" file="link6.stl"/>
      <mesh name="link7_c" file="link7.stl"/>

      <!-- Panda visual meshes -->
      <mesh file="link0_0.obj"/>
      <mesh file="link0_1.obj"/>
      <mesh file="link0_2.obj"/>
      <mesh file="link0_3.obj"/>
      <mesh file="link0_4.obj"/>
      <mesh file="link0_5.obj"/>
      <mesh file="link0_7.obj"/>
      <mesh file="link0_8.obj"/>
      <mesh file="link0_9.obj"/>
      <mesh file="link0_10.obj"/>
      <mesh file="link0_11.obj"/>
      <mesh file="link1.obj"/>
      <mesh file="link2.obj"/>
      <mesh file="link3_0.obj"/>
      <mesh file="link3_1.obj"/>
      <mesh file="link3_2.obj"/>
      <mesh file="link3_3.obj"/>
      <mesh file="link4_0.obj"/>
      <mesh file="link4_1.obj"/>
      <mesh file="link4_2.obj"/>
      <mesh file="link4_3.obj"/>
      <mesh file="link5_0.obj"/>
      <mesh file="link5_1.obj"/>
      <mesh file="link5_2.obj"/>
      <mesh file="link6_0.obj"/>
      <mesh file="link6_1.obj"/>
      <mesh file="link6_2.obj"/>
      <mesh file="link6_3.obj"/>
      <mesh file="link6_4.obj"/>
      <mesh file="link6_5.obj"/>
      <mesh file="link6_6.obj"/>
      <mesh file="link6_7.obj"/>
      <mesh file="link6_8.obj"/>
      <mesh file="link6_9.obj"/>
      <mesh file="link6_10.obj"/>
      <mesh file="link6_11.obj"/>
      <mesh file="link6_12.obj"/>
      <mesh file="link6_13.obj"/>
      <mesh file="link6_14.obj"/>
      <mesh file="link6_15.obj"/>
      <mesh file="link6_16.obj"/>
      <mesh file="link7_0.obj"/>
      <mesh file="link7_1.obj"/>
      <mesh file="link7_2.obj"/>
      <mesh file="link7_3.obj"/>
      <mesh file="link7_4.obj"/>
      <mesh file="link7_5.obj"/>
      <mesh file="link7_6.obj"/>
      <mesh file="link7_7.obj"/>

    <material name="metal" rgba="0.58 0.58 0.58 1"/>
    <material name="black" rgba="0.149 0.149 0.149 1"/>

    <mesh file="base.stl"/>
    <mesh file="base_coupling.stl"/>
    <mesh file="c-a01-85-open.stl"/>
    <mesh file="driver.stl"/>
    <mesh file="coupler.stl"/>
    <mesh file="spring_link.stl"/>
    <mesh file="follower.stl"/>
    <mesh file="tongue.stl"/>
    </asset>

  <contact>
 <exclude body1="base" body2="left_driver"/>
    <exclude body1="base" body2="right_driver"/>
    <exclude body1="base" body2="left_spring_link"/>
    <exclude body1="base" body2="right_spring_link"/>
    <exclude body1="right_coupler" body2="right_follower"/>
    <exclude body1="left_coupler" body2="left_follower"/>
  </contact>

    <!-- 5) WORLD BODY (Panda + Leap Hand) -->
    <worldbody>
      <light name="top" pos="0 0 2" mode="trackcom"/>

      <!-- link0 -->
      <body name="link0" childclass="panda">
        <inertial mass="0.629769" pos="-0.041018 -0.00014 0.049974"
                  fullinertia="0.00315 0.00388 0.004285 8.2904e-7 0.00015 8.2299e-6"/>
        <geom mesh="link0_0"  material="off_white" class="panda/visual"/>
        <geom mesh="link0_1"  material="dark_grey" class="panda/visual"/>
        <geom mesh="link0_2"  material="off_white" class="panda/visual"/>
        <geom mesh="link0_3"  material="dark_grey" class="panda/visual"/>
        <geom mesh="link0_4"  material="off_white" class="panda/visual"/>
        <geom mesh="link0_5"  material="dark_grey" class="panda/visual"/>
        <geom mesh="link0_7"  material="white" class="panda/visual"/>
        <geom mesh="link0_8"  material="white" class="panda/visual"/>
        <geom mesh="link0_9"  material="dark_grey" class="panda/visual"/>
        <geom mesh="link0_10" material="off_white" class="panda/visual"/>
        <geom mesh="link0_11" material="white" class="panda/visual"/>
        <geom mesh="link0_c"  class="panda/collision"/>

        <!-- link1 -->
        <body name="link1" pos="0 0 0.333">
          <inertial mass="4.970684" pos="0.003875 0.002081 -0.04762"
                    fullinertia="0.70337 0.70661 0.0091170 -0.00013900 0.0067720 0.019169"/>
          <joint name="joint1"/>
          <geom mesh="link1"   material="white" class="panda/visual"/>
          <geom mesh="link1_c" class="panda/collision"/>

          <!-- link2 -->
          <body name="link2" quat="1 -1 0 0">
            <inertial mass="0.646926" pos="-0.003141 -0.02872 0.003495"
                      fullinertia="0.0079620 2.8110e-2 2.5995e-2 -3.925e-3 1.0254e-2 7.04e-4"/>
            <joint name="joint2" range="-1.7628 1.7628"/>
            <geom mesh="link2"   material="white" class="panda/visual"/>
            <geom mesh="link2_c" class="panda/collision"/>

            <!-- link3 -->
            <body name="link3" pos="0 -0.316 0" quat="1 1 0 0">
              <joint name="joint3"/>
              <inertial mass="3.228604" pos="0.027518 0.039252 -0.066502"
                        fullinertia="0.037242 0.036155 0.01083 -0.004761 -0.011396 -0.012805"/>
              <geom mesh="link3_0" material="white"     class="panda/visual"/>
              <geom mesh="link3_1" material="white"     class="panda/visual"/>
              <geom mesh="link3_2" material="white"     class="panda/visual"/>
              <geom mesh="link3_3" material="dark_grey" class="panda/visual"/>
              <geom mesh="link3_c" class="panda/collision"/>

              <!-- link4 -->
              <body name="link4" pos="0.0825 0 0" quat="1 1 0 0">
                <inertial mass="3.587895" pos="-0.05317 0.104419 0.027454"
                          fullinertia="0.025853 0.019552 0.028323 0.007796 -0.001332 0.008641"/>
                <joint name="joint4" range="-3.0718 -0.0698"/>
                <geom mesh="link4_0" material="white"     class="panda/visual"/>
                <geom mesh="link4_1" material="white"     class="panda/visual"/>
                <geom mesh="link4_2" material="dark_grey" class="panda/visual"/>
                <geom mesh="link4_3" material="white"     class="panda/visual"/>
                <geom mesh="link4_c" class="panda/collision"/>

                <!-- link5 -->
                <body name="link5" pos="-0.0825 0.384 0" quat="1 -1 0 0">
                  <inertial mass="1.225946" pos="-0.011953 0.041065 -0.038437"
                            fullinertia="0.035549 0.029474 0.008627 -0.002117 -0.004037 0.000229"/>
                  <joint name="joint5"/>
                  <geom mesh="link5_0" material="dark_grey" class="panda/visual"/>
                  <geom mesh="link5_1" material="white"     class="panda/visual"/>
                  <geom mesh="link5_2" material="white"     class="panda/visual"/>
                  <geom mesh="link5_c0" class="panda/collision"/>
                  <geom mesh="link5_c1" class="panda/collision"/>
                  <geom mesh="link5_c2" class="panda/collision"/>

                  <!-- link6 -->
                  <body name="link6" quat="1 1 0 0">
                    <inertial mass="1.666555" pos="0.060149 -0.014117 -0.010517"
                              fullinertia="0.001964 0.004354 0.005433 0.000109 -0.001158 0.000341"/>
                    <joint name="joint6" range="-0.0175 3.7525"/>
                    <geom mesh="link6_0"  material="off_white" class="panda/visual"/>
                    <geom mesh="link6_1"  material="white"     class="panda/visual"/>
                    <geom mesh="link6_2"  material="dark_grey" class="panda/visual"/>
                    <geom mesh="link6_3"  material="white"     class="panda/visual"/>
                    <geom mesh="link6_4"  material="white"     class="panda/visual"/>
                    <geom mesh="link6_5"  material="white"     class="panda/visual"/>
                    <geom mesh="link6_6"  material="white"     class="panda/visual"/>
                    <geom mesh="link6_7"  material="light_blue" class="panda/visual"/>
                    <geom mesh="link6_8"  material="light_blue" class="panda/visual"/>
                    <geom mesh="link6_9"  material="dark_grey" class="panda/visual"/>
                    <geom mesh="link6_10" material="dark_grey" class="panda/visual"/>
                    <geom mesh="link6_11" material="white"     class="panda/visual"/>
                    <geom mesh="link6_12" material="green"     class="panda/visual"/>
                    <geom mesh="link6_13" material="white"     class="panda/visual"/>
                    <geom mesh="link6_14" material="dark_grey" class="panda/visual"/>
                    <geom mesh="link6_15" material="dark_grey" class="panda/visual"/>
                    <geom mesh="link6_16" material="white"     class="panda/visual"/>
                    <geom mesh="link6_c" class="panda/collision"/>

                    <!-- link7 -->
                    <body name="link7" pos="0.088 0 0" quat="1 1 0 0">
                      <inertial mass="0.735522" pos="0.010517 -0.004252 0.061597"
                                fullinertia="0.012516 0.010027 0.004815 -0.000428 -0.001196 -0.000741"/>
                      <joint name="joint7"/>
                      <geom mesh="link7_0" material="white"     class="panda/visual"/>
                      <geom mesh="link7_1" material="dark_grey" class="panda/visual"/>
                      <geom mesh="link7_2" material="dark_grey" class="panda/visual"/>
                      <geom mesh="link7_3" material="dark_grey" class="panda/visual"/>
                      <geom mesh="link7_4" material="dark_grey" class="panda/visual"/>
                      <geom mesh="link7_5" material="dark_grey" class="panda/visual"/>
                      <geom mesh="link7_6" material="dark_grey" class="panda/visual"/>
                      <geom mesh="link7_7" material="white"     class="panda/visual"/>
                      <geom mesh="link7_c" class="panda/collision"/>

                      <!-- Attachment body (no Panda hand) -->
                      <body name="attachment" pos="0 0 0.107" quat="0.3826834 0 0 0.9238795">
                        <site name="attachment_site"/>

         <body name="base" childclass="2f85">
      <inertial mass="0.777441" pos="0 -2.70394e-05 0.0354675" quat="1 -0.00152849 0 0"
        diaginertia="0.000260285 0.000225381 0.000152708"/>
      <geom class="visual" pos="0 0 0.0108" quat="0 0 0 1"   mesh="base"/>
      <geom class="visual" pos="0 0 0.004" quat="1 -1 0 0"   mesh="base_coupling"/>
      <geom class="visual" pos="0 0 0.0108" quat="1 0 0 0"  material="metal" mesh="c-a01-85-open"/>
      <geom class="collision" mesh="base"/>
      <!-- Left-hand side 4-bar linkage -->
      <body name="left_driver" pos="-0.0306011 0.00475 0.0657045" quat="1 -1 0 0">
        <inertial mass="0.00899563" pos="0 0.0177547 0.00107314" quat="0.681301 0.732003 0 0"
            diaginertia="1.72352e-06 1.60906e-06 3.22006e-07"/>
        <joint name="left_driver_joint" class="driver"/>
        <geom class="visual" pos="0.0306011 0.0549045 -0.0047" quat="1 1 0 0"  material="metal" mesh="driver"/>
        <geom class="collision" pos="0.0306011 0.0549045 -0.0047" quat="1 1 0 0"   mesh="driver"/>
        <body name="left_coupler" pos="-0.0314249 0.00453223 -0.0102" quat="0 0 0 1">
          <inertial mass="0.0140974" pos="0 0.00301209 0.0232175" quat="0.705636 -0.0455904 0.0455904 0.705636"
          diaginertia="4.16206e-06 3.52216e-06 8.88131e-07"/>
          <geom class="visual" pos="-0.062026 -0.0503723 0.0055" quat="1 -1 0 0"   mesh="coupler"/>
          <geom class="collision" pos="-0.062026 -0.0503723 0.0055" quat="1 -1 0 0"  mesh="coupler"/>
        </body>
      </body>
      <body name="left_spring_link" pos="-0.0127 -0.012 0.07222" quat="1 -1 0 0">
        <inertial mass="0.0221642" pos="-8.65005e-09 0.0181624 0.0212658" quat="0.663403 -0.244737 0.244737 0.663403"
            diaginertia="8.96853e-06 6.71733e-06 2.63931e-06"/>
        <joint name="left_spring_link_joint" class="spring_link"/>
        <geom class="visual" pos="0.0127 0.06142 0.01205" quat="1 1 0 0" type="mesh"  mesh="spring_link"/>
        <geom class="collision" pos="0.0127 0.06142 0.01205" quat="1 1 0 0" type="mesh"  mesh="spring_link"/>
        <body name="left_follower" pos="-0.0382079 -0.0425003 0.00295" quat="0 -1 -1.90231e-05 0">
          <inertial mass="0.0125222" pos="0 -0.011046 0.0124786" quat="1 0.1664 0 0"
          diaginertia="2.67415e-06 2.4559e-06 6.02031e-07"/>
          <joint name="left_follower" class="follower"/>
          <geom class="visual" pos="0.0509079 -0.10392 -0.0091" quat="1 -1 0 0" type="mesh"  mesh="follower"/>
          <geom class="visual" pos="0.0509079 -0.10392 -0.0091" quat="1 -1 0 0" type="mesh" material="metal" mesh="tongue"/>
          <geom class="collision" pos="0.0509079 -0.10392 -0.0091" quat="1 -1 0 0" type="mesh"  mesh="follower"/>
          <geom class="collision" pos="0.0509079 -0.10392 -0.0091" quat="1 -1 0 0" type="mesh"  mesh="tongue"/>
          <body name="left_pad" pos="-0.0377897 -0.103916 -0.0091" quat="1 -1 0 0" >
            <geom class="pad_box1" name="left_pad1"/>
            <geom class="pad_box2" name="left_pad2"/>
          </body>
        </body>
      </body>
      <!-- Right-hand side 4-bar linkage -->
      <body name="right_driver" pos="0.0306011 -0.00475 0.0657045" quat="0 0 -1 1">
        <inertial mass="0.00899563" pos="2.96931e-12 0.0177547 0.00107314" quat="0.681301 0.732003 0 0"
        diaginertia="1.72352e-06 1.60906e-06 3.22006e-07"/>
        <joint name="right_driver_joint" class="driver"/>
        <geom class="visual" pos="0.0306011 0.0549045 -0.0047" quat="1 1 0 0" material="metal" mesh="driver"/>
        <geom class="collision" pos="0.0306011 0.0549045 -0.0047" quat="1 1 0 0"  mesh="driver"/>
        <body name="right_coupler" pos="-0.0314249 0.00453223 -0.0102" quat="0 0 0 1">
          <inertial mass="0.0140974" pos="0 0.00301209 0.0232175" quat="0.705636 -0.0455904 0.0455904 0.705636"
          diaginertia="4.16206e-06 3.52216e-06 8.88131e-07"/>
          <geom class="visual" pos="-0.062026 -0.0503723 0.0055" quat="1 -1 0 0"   mesh="coupler"/>
          <geom class="collision" pos="-0.062026 -0.0503723 0.0055" quat="1 -1 0 0"   mesh="coupler"/>
        </body>
      </body>
      <body name="right_spring_link" pos="0.0127 0.012 0.07222" quat="0 0 -1 1">
        <inertial mass="0.0221642" pos="-8.65005e-09 0.0181624 0.0212658" quat="0.663403 -0.244737 0.244737 0.663403"
        diaginertia="8.96853e-06 6.71733e-06 2.63931e-06"/>
        <joint name="right_spring_link_joint" class="spring_link"/>
        <geom class="visual" pos="0.0127 0.06142 0.01205" quat="1 1 0 0"   mesh="spring_link"/>
        <geom class="collision" pos="0.0127 0.06142 0.01205" quat="1 1 0 0"   mesh="spring_link"/>
        <body name="right_follower" pos="-0.0382079 -0.0425003 0.00295" quat="0 -1 0 0">
          <inertial mass="0.0125222" pos="0 -0.011046 0.0124786" quat="1 0.1664 0 0"
          diaginertia="2.67415e-06 2.4559e-06 6.02031e-07"/>
          <joint name="right_follower_joint" class="follower"/>
          <geom class="visual" pos="0.0509079 -0.10392 -0.0091" quat="1 -1 0 0"  material="metal" mesh="tongue"/>
          <geom class="visual" pos="0.0509079 -0.10392 -0.0091" quat="1 -1 0 0"   mesh="follower"/>
          <geom class="collision" pos="0.0509079 -0.10392 -0.0091" quat="1 -1 0 0"   mesh="tongue"/>
          <geom class="collision" pos="0.0509079 -0.10392 -0.0091" quat="1 -1 0 0"   mesh="follower"/>
          <body name="right_pad" pos="-0.0377897 -0.103916 -0.0091"   quat="1 -1 0 0" >
            <geom class="pad_box1" name="right_pad1"/>
            <geom class="pad_box2" name="right_pad2"/>
          </body>
        </body>
      </body>
    </body>
                      </body> <!-- end of "attachment" -->
                    </body> <!-- end of link7 -->
                  </body> <!-- end of link6 -->
                </body> <!-- end of link5 -->
              </body> <!-- end of link4 -->
            </body> <!-- end of link3 -->
          </body> <!-- end of link2 -->
        </body> <!-- end of link1 -->
      </body> <!-- end of link0 -->
    </worldbody>

    <!-- 6) MERGED ACTUATORS -->
    <actuator>
      <!-- Panda Actuators -->
      <general class="panda" name="actuator1" joint="joint1" gainprm="4500" biasprm="0 -4500 -450"/>
      <general class="panda" name="actuator2" joint="joint2" gainprm="4500" biasprm="0 -4500 -450" ctrlrange="-1.7628 1.7628"/>
      <general class="panda" name="actuator3" joint="joint3" gainprm="3500" biasprm="0 -3500 -350"/>
      <general class="panda" name="actuator4" joint="joint4" gainprm="3500" biasprm="0 -3500 -350" ctrlrange="-3.0718 -0.0698"/>
      <general class="panda" name="actuator5" joint="joint5" gainprm="2000" biasprm="0 -2000 -200" forcerange="-12 12"/>
      <general class="panda" name="actuator6" joint="joint6" gainprm="2000" biasprm="0 -2000 -200" forcerange="-12 12" ctrlrange="-0.0175 3.7525"/>
      <general class="panda" name="actuator7" joint="joint7" gainprm="2000" biasprm="0 -2000 -200" forcerange="-12 12"/>

    <!-- Robotiq Actuator -->
    <general class="2f85" name="fingers_actuator" tendon="split" forcerange="-5 5" ctrlrange="0 255"
      gainprm="0.3137255 0 0" biasprm="0 -100 -10"/>
    </actuator>
    
  <tendon>
    <fixed name="split">
      <joint joint="right_driver_joint" coef="0.485"/>
      <joint joint="left_driver_joint" coef="0.485"/>
    </fixed>
  </tendon>

  <equality>
    <connect anchor="-0.0179014 -0.00651468 0.0044" body1="right_follower" body2="right_coupler" solimp="0.95 0.99 0.001" solref="0.005 1"/>
    <connect anchor="-0.0179014 -0.00651468 0.0044" body1="left_follower" body2="left_coupler" solimp="0.95 0.99 0.001" solref="0.005 1"/>
    <joint joint1="right_driver_joint" joint2="left_driver_joint" polycoef="0 1 0 0 0" solimp="0.95 0.99 0.001"
    solref="0.005 1"/>
  </equality>

</mujoco>

